<?xml version="1.0"?>
<robot name="cylindrical_diff_drive_robot">

  <link name="base_link">
    <inertial>
      <mass value="2.0" />  <inertia ixx="0.001" ixy="0.0" ixz="0.0" iyx="0.0" iyy="0.001" iyz="0.0" izx="0.0" izy="0.0" izz="0.001" />
    </inertial>
    <visual>
      <origin xyz="0 0 0.075" />  <geometry>
        <cylinder radius="0.18" length="0.15" />
      </geometry>
      <material name="Blue">
        <color rgba="0 0 1 1" />
      </material>
    </visual>
  </link>

  <joint name="left_wheel_joint" type="revolute" axis="1 0 0">
    <parent link="base_link" />
    <child link="left_wheel_link" />
    <origin xyz="0.18 0.0 0.03" />  <axis xyz="1 0 0" />
    <limit lower="-1.57" upper="1.57" effort="10" velocity="10" />  </joint>

  <joint name="right_wheel_joint" type="revolute" axis="1 0 0">
    <parent link="base_link" />
    <child link="right_wheel_link" />
    <origin xyz="-0.18 0.0 0.03" />  <axis xyz="1 0 0" />
    <limit lower="-1.57" upper="1.57" effort="10" velocity="10" />  </joint>

  <link name="left_wheel_link">
    <inertial>
      <mass value="0.5" />  <inertia ixx="0.0005" ixy="0.0" ixz="0.0" iyx="0.0" iyy="0.0005" iyz="0.0" izx="0.0" izy="0.0" izz="0.0005" />
    </inertial>
    <visual>
      <origin xyz="0 0 0" />
      <geometry>
        <cylinder radius="0.03" length="0.06" />
      </geometry>
      <material name="Black">
        <color rgba="0 0 0 1" />
      </material>
    </visual>
  </link>

  <link name="right_wheel_link">
    <inertial>
      <mass value="0.5" />  <inertia ixx="0.0005" ixy="0.0" ixz="0.0" iyx="0.0" iyy="0.0005" iyz="0.0" izx="0.0" izy="0.0" izz="0.0005" />
    </inertial>
    <visual>
      <origin xyz="0 0 0" />
      <geometry>
        <cylinder radius="0.03" length="0.06" />
      </geometry>
      <material name="Black">
        <color rgba="0 0 0 1" />
      </material>
    </visual>
  </link>

</robot>
